{
  "nbformat": 4,
  "nbformat_minor": 0,
  "metadata": {
    "colab": {
      "provenance": [],
      "authorship_tag": "ABX9TyNbjWcfGgYfIZw9r6r4y88O",
      "include_colab_link": true
    },
    "kernelspec": {
      "name": "python3",
      "display_name": "Python 3"
    },
    "language_info": {
      "name": "python"
    }
  },
  "cells": [
    {
      "cell_type": "markdown",
      "metadata": {
        "id": "view-in-github",
        "colab_type": "text"
      },
      "source": [
        "<a href=\"https://colab.research.google.com/github/sames12421/face_reconnization/blob/main/facerec.ipynb\" target=\"_parent\"><img src=\"https://colab.research.google.com/assets/colab-badge.svg\" alt=\"Open In Colab\"/></a>"
      ]
    },
    {
      "cell_type": "markdown",
      "source": [
        "# hog method is use\n",
        "delive will capture the landmark basedon that they will train one already present neural network to reconozie the face present\n",
        "\n",
        "\n",
        "1  encodeing feature = different b/w eye nose distace of each image and generate 128 measurements we can define a person\n",
        "\n",
        "2 differentciate them = and we can have linear model of these"
      ],
      "metadata": {
        "id": "U7lCS5RTNE-c"
      }
    },
    {
      "cell_type": "code",
      "execution_count": null,
      "metadata": {
        "colab": {
          "base_uri": "https://localhost:8080/",
          "height": 321
        },
        "id": "Nhp7GaI8M4wb",
        "outputId": "60a3f93e-8acc-457a-ee3a-df4053614cd5"
      },
      "outputs": [
        {
          "output_type": "error",
          "ename": "RuntimeError",
          "evalue": "Error while calling cudaGetDevice(&the_device_id) in file /tmp/pip-install-wo2pihw_/dlib_c7bc88348fbb41f6942a2049b1615d49/dlib/cuda/gpu_data.cpp:204. code: 35, reason: CUDA driver version is insufficient for CUDA runtime version",
          "traceback": [
            "\u001b[0;31m---------------------------------------------------------------------------\u001b[0m",
            "\u001b[0;31mRuntimeError\u001b[0m                              Traceback (most recent call last)",
            "\u001b[0;32m<ipython-input-14-74d19ccc7330>\u001b[0m in \u001b[0;36m<cell line: 2>\u001b[0;34m()\u001b[0m\n\u001b[1;32m      1\u001b[0m \u001b[0;32mimport\u001b[0m \u001b[0mnumpy\u001b[0m \u001b[0;32mas\u001b[0m \u001b[0mnp\u001b[0m\u001b[0;34m\u001b[0m\u001b[0;34m\u001b[0m\u001b[0m\n\u001b[0;32m----> 2\u001b[0;31m \u001b[0;32mimport\u001b[0m \u001b[0mface_recognition\u001b[0m \u001b[0;32mas\u001b[0m \u001b[0mfr\u001b[0m\u001b[0;34m\u001b[0m\u001b[0;34m\u001b[0m\u001b[0m\n\u001b[0m",
            "\u001b[0;32m/usr/local/lib/python3.10/dist-packages/face_recognition/__init__.py\u001b[0m in \u001b[0;36m<module>\u001b[0;34m\u001b[0m\n\u001b[1;32m      5\u001b[0m \u001b[0m__version__\u001b[0m \u001b[0;34m=\u001b[0m \u001b[0;34m'1.2.3'\u001b[0m\u001b[0;34m\u001b[0m\u001b[0;34m\u001b[0m\u001b[0m\n\u001b[1;32m      6\u001b[0m \u001b[0;34m\u001b[0m\u001b[0m\n\u001b[0;32m----> 7\u001b[0;31m \u001b[0;32mfrom\u001b[0m \u001b[0;34m.\u001b[0m\u001b[0mapi\u001b[0m \u001b[0;32mimport\u001b[0m \u001b[0mload_image_file\u001b[0m\u001b[0;34m,\u001b[0m \u001b[0mface_locations\u001b[0m\u001b[0;34m,\u001b[0m \u001b[0mbatch_face_locations\u001b[0m\u001b[0;34m,\u001b[0m \u001b[0mface_landmarks\u001b[0m\u001b[0;34m,\u001b[0m \u001b[0mface_encodings\u001b[0m\u001b[0;34m,\u001b[0m \u001b[0mcompare_faces\u001b[0m\u001b[0;34m,\u001b[0m \u001b[0mface_distance\u001b[0m\u001b[0;34m\u001b[0m\u001b[0;34m\u001b[0m\u001b[0m\n\u001b[0m",
            "\u001b[0;32m/usr/local/lib/python3.10/dist-packages/face_recognition/api.py\u001b[0m in \u001b[0;36m<module>\u001b[0;34m\u001b[0m\n\u001b[1;32m     24\u001b[0m \u001b[0;34m\u001b[0m\u001b[0m\n\u001b[1;32m     25\u001b[0m \u001b[0mcnn_face_detection_model\u001b[0m \u001b[0;34m=\u001b[0m \u001b[0mface_recognition_models\u001b[0m\u001b[0;34m.\u001b[0m\u001b[0mcnn_face_detector_model_location\u001b[0m\u001b[0;34m(\u001b[0m\u001b[0;34m)\u001b[0m\u001b[0;34m\u001b[0m\u001b[0;34m\u001b[0m\u001b[0m\n\u001b[0;32m---> 26\u001b[0;31m \u001b[0mcnn_face_detector\u001b[0m \u001b[0;34m=\u001b[0m \u001b[0mdlib\u001b[0m\u001b[0;34m.\u001b[0m\u001b[0mcnn_face_detection_model_v1\u001b[0m\u001b[0;34m(\u001b[0m\u001b[0mcnn_face_detection_model\u001b[0m\u001b[0;34m)\u001b[0m\u001b[0;34m\u001b[0m\u001b[0;34m\u001b[0m\u001b[0m\n\u001b[0m\u001b[1;32m     27\u001b[0m \u001b[0;34m\u001b[0m\u001b[0m\n\u001b[1;32m     28\u001b[0m \u001b[0mface_recognition_model\u001b[0m \u001b[0;34m=\u001b[0m \u001b[0mface_recognition_models\u001b[0m\u001b[0;34m.\u001b[0m\u001b[0mface_recognition_model_location\u001b[0m\u001b[0;34m(\u001b[0m\u001b[0;34m)\u001b[0m\u001b[0;34m\u001b[0m\u001b[0;34m\u001b[0m\u001b[0m\n",
            "\u001b[0;31mRuntimeError\u001b[0m: Error while calling cudaGetDevice(&the_device_id) in file /tmp/pip-install-wo2pihw_/dlib_c7bc88348fbb41f6942a2049b1615d49/dlib/cuda/gpu_data.cpp:204. code: 35, reason: CUDA driver version is insufficient for CUDA runtime version"
          ]
        }
      ],
      "source": [
        "import numpy as np\n",
        "import face_recognition as fr"
      ]
    },
    {
      "cell_type": "code",
      "source": [
        "!pip install face_recognition\n"
      ],
      "metadata": {
        "colab": {
          "base_uri": "https://localhost:8080/"
        },
        "id": "u8Z4uaKWO1_E",
        "outputId": "6a0da1d0-9392-4627-8226-645b12d05f71"
      },
      "execution_count": null,
      "outputs": [
        {
          "output_type": "stream",
          "name": "stdout",
          "text": [
            "Requirement already satisfied: face_recognition in /usr/local/lib/python3.10/dist-packages (1.3.0)\n",
            "Requirement already satisfied: face-recognition-models>=0.3.0 in /usr/local/lib/python3.10/dist-packages (from face_recognition) (0.3.0)\n",
            "Requirement already satisfied: Click>=6.0 in /usr/local/lib/python3.10/dist-packages (from face_recognition) (8.1.7)\n",
            "Requirement already satisfied: dlib>=19.7 in /usr/local/lib/python3.10/dist-packages (from face_recognition) (19.24.2)\n",
            "Requirement already satisfied: numpy in /usr/local/lib/python3.10/dist-packages (from face_recognition) (1.26.4)\n",
            "Requirement already satisfied: Pillow in /usr/local/lib/python3.10/dist-packages (from face_recognition) (10.4.0)\n"
          ]
        }
      ]
    },
    {
      "cell_type": "code",
      "source": [
        "!python -m venv myenv"
      ],
      "metadata": {
        "colab": {
          "base_uri": "https://localhost:8080/"
        },
        "id": "EJD3JabzP0N8",
        "outputId": "f651c595-c700-4e5c-8ff0-5d44f0eb8cc3"
      },
      "execution_count": null,
      "outputs": [
        {
          "output_type": "stream",
          "name": "stdout",
          "text": [
            "The virtual environment was not created successfully because ensurepip is not\n",
            "available.  On Debian/Ubuntu systems, you need to install the python3-venv\n",
            "package using the following command.\n",
            "\n",
            "    apt install python3.10-venv\n",
            "\n",
            "You may need to use sudo with that command.  After installing the python3-venv\n",
            "package, recreate your virtual environment.\n",
            "\n",
            "Failing command: /content/myenv/bin/python3\n",
            "\n"
          ]
        }
      ]
    },
    {
      "cell_type": "code",
      "source": [
        "!myenv\\Scripts\\activate"
      ],
      "metadata": {
        "colab": {
          "base_uri": "https://localhost:8080/"
        },
        "id": "ShaGUggzP9iM",
        "outputId": "47acf193-169c-4459-83c6-84c93feba9ad"
      },
      "execution_count": null,
      "outputs": [
        {
          "output_type": "stream",
          "name": "stdout",
          "text": [
            "/bin/bash: line 1: myenvScriptsactivate: command not found\n"
          ]
        }
      ]
    },
    {
      "cell_type": "code",
      "source": [
        " ! pip install face_recognition\n"
      ],
      "metadata": {
        "colab": {
          "base_uri": "https://localhost:8080/"
        },
        "id": "fJor9rEMQD8c",
        "outputId": "c4c5eb52-82c9-46db-d26d-6eb4e19c169c"
      },
      "execution_count": null,
      "outputs": [
        {
          "output_type": "stream",
          "name": "stdout",
          "text": [
            "Requirement already satisfied: face_recognition in /usr/local/lib/python3.10/dist-packages (1.3.0)\n",
            "Requirement already satisfied: face-recognition-models>=0.3.0 in /usr/local/lib/python3.10/dist-packages (from face_recognition) (0.3.0)\n",
            "Requirement already satisfied: Click>=6.0 in /usr/local/lib/python3.10/dist-packages (from face_recognition) (8.1.7)\n",
            "Requirement already satisfied: dlib>=19.7 in /usr/local/lib/python3.10/dist-packages (from face_recognition) (19.24.2)\n",
            "Requirement already satisfied: numpy in /usr/local/lib/python3.10/dist-packages (from face_recognition) (1.26.4)\n",
            "Requirement already satisfied: Pillow in /usr/local/lib/python3.10/dist-packages (from face_recognition) (10.4.0)\n"
          ]
        }
      ]
    }
  ]
}